Workbook
Name cop: #REF!
Name Slicer_City: #REF!

Sheet data
A1: Customer_ID | B1: First_Name | C1: Last_Name | D1: Age | E1: Gender | F1: City | G1: Email | H1: Address | I1: Order_ID | J1: Order_Date | K1: Order_Time | L1: Product_ID | M1: Price | N1: Quantity | O1: Coupon_Code | P1: Estimated_Days_to_Deliver | Q1: Delivery_Charge | R1: Delivery_Date | S1: Delivery_Time
A2: CID186 | B2: Anne | C2: Oconnell | D2: 37 | E2: Male | F2: Phoenix | G2: anne.oconnell@outlook.com | H2: 2850 Matthew Ford, North Yolandachester, FL 67488 | I2: OID2497 | J2: 45358 | K2: 18:16:33 | L2: PID022 | M2: 308.88 | N2: 5 | O2: FLAT8 | P2: 4 | Q2: 60 | R2: 45361 | S2: 08:51:31
A3: CID150 | B3: Anthony | C3: Thomas | D3: 53 | E3: Female | F3: Houston | G3: anthony.thomas@rediffmail.com | H3: 931 Christopher Ways Suite 833, North Michelle, IN 53484 | I3: OID7056 | J3: 45378 | K3: 01:46:33 | L3: PID015 | M3: 166.28 | N3: 4 | O3: FLAT8 | P3: 7 | Q3: 66 | R3: 45381 | S3: 18:46:26
A4: CID115 | B4: Karl | C4: Gallagher | D4: 60 | E4: Other | F4: Phoenix | G4: karl.gallagher@rediffmail.com | H4: 5016 Snow Mountains Apt. 063, New Seanport, WY 41492 | I4: OID7502 | J4: 45342 | K4: 07:31:36 | L4: PID023 | M4: 202.54 | N4: 1 | O4: FLAT15 | P4: 3 | Q4: 47 | R4: 45344 | S4: 14:29:50
A5: CID115 | B5: Karl | C5: Gallagher | D5: 60 | E5: Other | F5: Phoenix | G5: karl.gallagher@rediffmail.com | H5: 5016 Snow Mountains Apt. 063, New Seanport, WY 41492 | I5: OID7077 | J5: 45426 | K5: 18:29:21 | L5: PID031 | M5: 405 | N5: 5 | O5: DEL0 | P5: 6 | Q5: 47 | R5: 45430 | S5: 07:00:32
A6: CID149 | B6: Angela | C6: Horne | D6: 49 | E6: Other | F6: Phoenix | G6: angela.horne@outlook.com | H6: USNV Mueller, FPO AP 54648 | I6: OID2793 | J6: 45391 | K6: 03:23:21 | L6: PID015 | M6: 166.28 | N6: 1 | O6: FLAT8 | P6: 2 | Q6: 54 | R6: 45395 | S6: 22:10:58
A7: CID159 | B7: Christine | C7: West | D7: 53 | E7: Other | F7: New York | G7: christine.west@gmail.com | H7: Unit 1433 Box 0246, DPO AP 94952 | I7: OID1483 | J7: 45543 | K7: 16:55:06 | L7: PID043 | M7: 330.11 | N7: 4 | O7: FLAT15 | P7: 6 | Q7: 39 | R7: 45547 | S7: 11:25:50
A8: CID115 | B8: Karl | C8: Gallagher | D8: 60 | E8: Other | F8: Phoenix | G8: karl.gallagher@rediffmail.com | H8: 5016 Snow Mountains Apt. 063, New Seanport, WY 41492 | I8: OID4105 | J8: 45662 | K8: 09:47:21 | L8: PID022 | M8: 308.88 | N8: 5 | O8: FLAT20 | P8: 5 | Q8: 47 | R8: 45665 | S8: 20:10:50
A9: CID198 | B9: David | C9: Delacruz | D9: 26 | E9: Female | F9: Los Angeles | G9: david.delacruz@rediffmail.com | H9: USNS Ray, FPO AE 20238 | I9: OID4372 | J9: 45459 | K9: 19:27:45 | L9: PID046 | M9: 363.64 | N9: 3 | O9: FLAT10 | P9: 2 | Q9: 70 | R9: 45464 | S9: 12:36:32
A10: CID152 | B10: Marcus | C10: Valenzuela | D10: 39 | E10: Male | F10: Phoenix | G10: marcus.valenzuela@yahoo.com | H10: 694 Graham Prairie Apt. 887, Jimenezfurt, MI 33044 | I10: OID3528 | J10: 45040 | K10: 12:07:00 | L10: PID034 | M10: 275.44 | N10: 1 | O10: FLAT8 | P10: 7 | Q10: 63 | R10: 45042 | S10: 23:05:41
A11: CID130 | B11: Debra | C11: Rodriguez | D11: 48 | E11: Other | F11: Houston | G11: debra.rodriguez@rediffmail.com | H11: Unit 5964 Box 0721, DPO AP 01840 | I11: OID9634 | J11: 45282 | K11: 13:46:47 | L11: PID033 | M11: 48.45 | N11: 1 | O11: FLAT15 | P11: 7 | Q11: 59 | R11: 45287 | S11: 19:57:06
A12: CID115 | B12: Karl | C12: Gallagher | D12: 60 | E12: Other | F12: Phoenix | G12: karl.gallagher@rediffmail.com | H12: 5016 Snow Mountains Apt. 063, New Seanport, WY 41492 | I12: OID1905 | J12: 45588 | K12: 17:21:43 | L12: PID046 | M12: 363.64 | N12: 4 | O12: DEL0 | P12: 2 | Q12: 35 | R12: 45590 | S12: 08:00:35
A13: CID101 | B13: Bobby | C13: Forbes | D13: 20 | E13: Male | F13: Los Angeles | G13: bobby.forbes@gmail.com | H13: 3079 John Parkway Suite 961, Port Kristaview, MT 91019 | I13: OID3136 | J13: 45498 | K13: 15:09:49 | L13: PID007 | M13: 257.06 | N13: 3 | O13: DEL0 | P13: 7 | Q13: 62 | R13: 45499 | S13: 22:54:40
... A501: CID158 | B501: Angela | C501: Evans | D501: 52 | E501: Other | F501: Houston | G501: angela.evans@outlook.com | H501: 16031 David Mountain Suite 431, Susanborough, PA 01910 | I501: OID6847 | J501: 45501 | K501: 17:02:09 | L501: PID010 | M501: 44.5 | N501: 4 | O501: DEL0 | P501: 3 | Q501: 45 | R501: 45504 | S501: 05:55:32

Sheet Ques
B2: Q1) Count of distinct Customer
B4: Q2) Count of distinct Products
B6: Q3) Create a new column, Days to deliver and fill it with number of days it took for delivery
B8: Q4) Create a new column Amount by using Price and Quantity
B10: Q5) Create a new column for Amount_with_Del_Chrg considering Delivery Charge as well
B12: Q6) Create a new column Discount_Percent and use Coupon_Code to Extract it.
B13: FLAT8 implies 8% discount, FLAT10 implies 10% discount. FLAT15 implies 15% discount, FLAT20 implies 20% discount, DEL0 implies No Delivery charge would be applied
B15: Q7) Compute final amount by using Amount_with_Del_Chrg and Discount_Percent
B17: Q8) Generate a Column Full_name by utilising FirstName and Last Name
B19: Q9) Create new columns - Fname, Lname by extracting First_Name and Last_name from the Full_Name column enerated in Q8
B21: Q10) Create a new column - MobileNum by Extracting Contact details excluding the +1-
B24: Other Ques
... B54: Q7) Create a pivot table to represent count of different disocunt coupons and free delivery coupons. Represent it on a donut chart

Sheet Solutions
A1: Customer_ID | B1: First_Name | C1: Last_Name | D1: Age | E1: Gender | F1: City | G1: Email | H1: Contact | I1: Address | J1: Order_ID | K1: Order_Date | L1: Order_Time | M1: Product_ID | N1: Price | O1: Quantity | P1: Coupon_Code | Q1: Estimated_Days_to_Deliver | R1: Delivery_Charge | S1: Delivery_Date | T1: Delivery_Time | U1: Days to Deliver | V1: Order_Hour | W1: Amount | X1: Amount with Del Charg | Y1: Discount_Percent | Z1: Discounted_Amt | AA1: Final Amount | AB1: Order_Day | AC1: Is_Weekend | AD1: User_Name | AE1: Domain | AF1: Full_Name | AG1: Fname | AH1: Lname | AI1: Delivery_Status | AJ1: Mobile_Num
A2: CID186 | B2: Anne | C2: Oconnell | D2: 37 | E2: Male | F2: Phoenix | G2: anne.oconnell@outlook.com | H2: +1-1907565656 | I2: 2850 Matthew Ford, North Yolandachester, FL 67488 | J2: OID2497 | K2: 45358 | L2: 18:16:33 | M2: PID022 | N2: 308.88 | O2: 5 | P2: FLAT8 | Q2: 4 | R2: 60 | S2: 45361 | T2: 08:51:31 | U2: =VALUE(DATEDIF(K2,S2,"D")) -> 3 | V2: =HOUR(L2) -> 18 | W2: =N2*O2 -> 1544.4 | X2: =W2+R2 -> 1604.4 | Y2: =IFERROR(NUMBERVALUE(RIGHT(P2,LEN(P2)-SEARCH("T",P2,1))),0) -> 0 | Z2: =W2-(W2*Y2)/100 -> 1544.4 | AA2: =IF(P2="DEL0", Z2, Z2+ R2) -> 1604.4 | AB2: =TEXT(K2,"dddd") -> Thursday | AC2: =IF(OR(AB2="Saturday",AB2="Sunday"),"Weekend","Weekday") -> Weekday | AD2: =LEFT(G2,SEARCH("@",G2,1)-1) -> anne.oconnell | AE2: =MID(G2, SEARCH("@",G2,1)+1, SEARCH(".",G2,SEARCH(".",G2,1)+1) - SEARCH("@",G2,1)-1) -> outlook | AF2: =B2 & " " & C2 -> Anne Oconnell | AG2: =LEFT(AF2,SEARCH(" ",AF2,1)-1) -> Anne | AH2: =RIGHT(AF2,LEN(AF2)-SEARCH(" ",AF2,1)) -> Oconnell | AI2: =IF(Q2>U2, "Before Time", IF(Q2=U2,"InTime","Late")) -> Before Time | AJ2: =NUMBERVALUE(RIGHT(H2,LEN(H2)-SEARCH("-",H2))) -> #NAME?
A3: CID150 | B3: Anthony | C3: Thomas | D3: 53 | E3: Female | F3: Houston | G3: anthony.thomas@rediffmail.com | H3: +1-1365605012 | I3: 931 Christopher Ways Suite 833, North Michelle, IN 53484 | J3: OID7056 | K3: 45378 | L3: 01:46:33 | M3: PID015 | N3: 166.28 | O3: 4 | P3: FLAT8 | Q3: 7 | R3: 66 | S3: 45381 | T3: 18:46:26 | U3: =VALUE(DATEDIF(K3,S3,"D")) -> 3 | V3: =HOUR(L3) -> 1 | W3: =N3*O3 -> 665.12 | X3: =W3+R3 -> 731.12 | Y3: =IFERROR(NUMBERVALUE(RIGHT(P3,LEN(P3)-SEARCH("T",P3,1))),0) -> 0 | Z3: =W3-(W3*Y3)/100 -> 665.12 | AA3: =IF(P3="DEL0", Z3, Z3+ R3) -> 731.12 | AB3: =TEXT(K3,"dddd") -> Wednesday | AC3: =IF(OR(AB3="Saturday",AB3="Sunday"),"Weekend","Weekday") -> Weekday | AD3: =LEFT(G3,SEARCH("@",G3,1)-1) -> anthony.thomas | AE3: =MID(G3, SEARCH("@",G3,1)+1, SEARCH(".",G3,SEARCH(".",G3,1)+1) - SEARCH("@",G3,1)-1) -> rediffmail | AF3: =B3 & " " & C3 -> Anthony Thomas | AG3: =LEFT(AF3,SEARCH(" ",AF3,1)-1) -> Anthony | AH3: =RIGHT(AF3,LEN(AF3)-SEARCH(" ",AF3,1)) -> Thomas | AI3: =IF(Q3>U3, "Before Time", IF(Q3=U3,"InTime","Late")) -> Before Time | AJ3: =NUMBERVALUE(RIGHT(H3,LEN(H3)-SEARCH("-",H3))) -> #NAME?
A4: CID115 | B4: Karl | C4: Gallagher | D4: 60 | E4: Other | F4: Phoenix | G4: karl.gallagher@rediffmail.com | H4: +1-2802179041 | I4: 5016 Snow Mountains Apt. 063, New Seanport, WY 41492 | J4: OID7502 | K4: 45342 | L4: 07:31:36 | M4: PID023 | N4: 202.54 | O4: 1 | P4: FLAT15 | Q4: 3 | R4: 47 | S4: 45344 | T4: 14:29:50 | U4: =VALUE(DATEDIF(K4,S4,"D")) -> 2 | V4: =HOUR(L4) -> 7 | W4: =N4*O4 -> 202.54 | X4: =W4+R4 -> 249.54 | Y4: =IFERROR(NUMBERVALUE(RIGHT(P4,LEN(P4)-SEARCH("T",P4,1))),0) -> 0 | Z4: =W4-(W4*Y4)/100 -> 202.54 | AA4: =IF(P4="DEL0", Z4, Z4+ R4) -> 249.54 | AB4: =TEXT(K4,"dddd") -> Tuesday | AC4: =IF(OR(AB4="Saturday",AB4="Sunday"),"Weekend","Weekday") -> Weekday | AD4: =LEFT(G4,SEARCH("@",G4,1)-1) -> karl.gallagher | AE4: =MID(G4, SEARCH("@",G4,1)+1, SEARCH(".",G4,SEARCH(".",G4,1)+1) - SEARCH("@",G4,1)-1) -> rediffmail | AF4: =B4 & " " & C4 -> Karl Gallagher | AG4: =LEFT(AF4,SEARCH(" ",AF4,1)-1) -> Karl | AH4: =RIGHT(AF4,LEN(AF4)-SEARCH(" ",AF4,1)) -> Gallagher | AI4: =IF(Q4>U4, "Before Time", IF(Q4=U4,"InTime","Late")) -> Before Time | AJ4: =NUMBERVALUE(RIGHT(H4,LEN(H4)-SEARCH("-",H4))) -> #NAME?
A5: CID115 | B5: Karl | C5: Gallagher | D5: 60 | E5: Other | F5: Phoenix | G5: karl.gallagher@rediffmail.com | H5: +1-2802179041 | I5: 5016 Snow Mountains Apt. 063, New Seanport, WY 41492 | J5: OID7077 | K5: 45426 | L5: 18:29:21 | M5: PID031 | N5: 405 | O5: 5 | P5: DEL0 | Q5: 6 | R5: 47 | S5: 45430 | T5: 07:00:32 | U5: =VALUE(DATEDIF(K5,S5,"D")) -> 4 | V5: =HOUR(L5) -> 18 | W5: =N5*O5 -> 2025 | X5: =W5+R5 -> 2072 | Y5: =IFERROR(NUMBERVALUE(RIGHT(P5,LEN(P5)-SEARCH("T",P5,1))),0) -> 0 | Z5: =W5-(W5*Y5)/100 -> 2025 | AA5: =IF(P5="DEL0", Z5, Z5+ R5) -> 2025 | AB5: =TEXT(K5,"dddd") -> Tuesday | AC5: =IF(OR(AB5="Saturday",AB5="Sunday"),"Weekend","Weekday") -> Weekday | AD5: =LEFT(G5,SEARCH("@",G5,1)-1) -> karl.gallagher | AE5: =MID(G5, SEARCH("@",G5,1)+1, SEARCH(".",G5,SEARCH(".",G5,1)+1) - SEARCH("@",G5,1)-1) -> rediffmail | AF5: =B5 & " " & C5 -> Karl Gallagher | AG5: =LEFT(AF5,SEARCH(" ",AF5,1)-1) -> Karl | AH5: =RIGHT(AF5,LEN(AF5)-SEARCH(" ",AF5,1)) -> Gallagher | AI5: =IF(Q5>U5, "Before Time", IF(Q5=U5,"InTime","Late")) -> Before Time | AJ5: =NUMBERVALUE(RIGHT(H5,LEN(H5)-SEARCH("-",H5))) -> #NAME?
A6: CID149 | B6: Angela | C6: Horne | D6: 49 | E6: Other | F6: Phoenix | G6: angela.horne@outlook.com | H6: +1-3002859425 | I6: USNV Mueller, FPO AP 54648 | J6: OID2793 | K6: 45391 | L6: 03:23:21 | M6: PID015 | N6: 166.28 | O6: 1 | P6: FLAT8 | Q6: 2 | R6: 54 | S6: 45395 | T6: 22:10:58 | U6: =VALUE(DATEDIF(K6,S6,"D")) -> 4 | V6: =HOUR(L6) -> 3 | W6: =N6*O6 -> 166.28 | X6: =W6+R6 -> 220.28 | Y6: =IFERROR(NUMBERVALUE(RIGHT(P6,LEN(P6)-SEARCH("T",P6,1))),0) -> 0 | Z6: =W6-(W6*Y6)/100 -> 166.28 | AA6: =IF(P6="DEL0", Z6, Z6+ R6) -> 220.28 | AB6: =TEXT(K6,"dddd") -> Tuesday | AC6: =IF(OR(AB6="Saturday",AB6="Sunday"),"Weekend","Weekday") -> Weekday | AD6: =LEFT(G6,SEARCH("@",G6,1)-1) -> angela.horne | AE6: =MID(G6, SEARCH("@",G6,1)+1, SEARCH(".",G6,SEARCH(".",G6,1)+1) - SEARCH("@",G6,1)-1) -> outlook | AF6: =B6 & " " & C6 -> Angela Horne | AG6: =LEFT(AF6,SEARCH(" ",AF6,1)-1) -> Angela | AH6: =RIGHT(AF6,LEN(AF6)-SEARCH(" ",AF6,1)) -> Horne | AI6: =IF(Q6>U6, "Before Time", IF(Q6=U6,"InTime","Late")) -> Late | AJ6: =NUMBERVALUE(RIGHT(H6,LEN(H6)-SEARCH("-",H6))) -> #NAME?
A7: CID159 | B7: Christine | C7: West | D7: 53 | E7: Other | F7: New York | G7: christine.west@gmail.com | H7: +1-9124531645 | I7: Unit 1433 Box 0246, DPO AP 94952 | J7: OID1483 | K7: 45543 | L7: 16:55:06 | M7: PID043 | N7: 330.11 | O7: 4 | P7: FLAT15 | Q7: 6 | R7: 39 | S7: 45547 | T7: 11:25:50 | U7: =VALUE(DATEDIF(K7,S7,"D")) -> 4 | V7: =HOUR(L7) -> 16 | W7: =N7*O7 -> 1320.44 | X7: =W7+R7 -> 1359.44 | Y7: =IFERROR(NUMBERVALUE(RIGHT(P7,LEN(P7)-SEARCH("T",P7,1))),0) -> 0 | Z7: =W7-(W7*Y7)/100 -> 1320.44 | AA7: =IF(P7="DEL0", Z7, Z7+ R7) -> 1359.44 | AB7: =TEXT(K7,"dddd") -> Sunday | AC7: =IF(OR(AB7="Saturday",AB7="Sunday"),"Weekend","Weekday") -> Weekend | AD7: =LEFT(G7,SEARCH("@",G7,1)-1) -> christine.west | AE7: =MID(G7, SEARCH("@",G7,1)+1, SEARCH(".",G7,SEARCH(".",G7,1)+1) - SEARCH("@",G7,1)-1) -> gmail | AF7: =B7 & " " & C7 -> Christine West | AG7: =LEFT(AF7,SEARCH(" ",AF7,1)-1) -> Christine | AH7: =RIGHT(AF7,LEN(AF7)-SEARCH(" ",AF7,1)) -> West | AI7: =IF(Q7>U7, "Before Time", IF(Q7=U7,"InTime","Late")) -> Before Time | AJ7: =NUMBERVALUE(RIGHT(H7,LEN(H7)-SEARCH("-",H7))) -> #NAME?
A8: CID115 | B8: Karl | C8: Gallagher | D8: 60 | E8: Other | F8: Phoenix | G8: karl.gallagher@rediffmail.com | H8: +1-2802179041 | I8: 5016 Snow Mountains Apt. 063, New Seanport, WY 41492 | J8: OID4105 | K8: 45662 | L8: 09:47:21 | M8: PID022 | N8: 308.88 | O8: 5 | P8: FLAT20 | Q8: 5 | R8: 47 | S8: 45665 | T8: 20:10:50 | U8: =VALUE(DATEDIF(K8,S8,"D")) -> 3 | V8: =HOUR(L8) -> 9 | W8: =N8*O8 -> 1544.4 | X8: =W8+R8 -> 1591.4 | Y8: =IFERROR(NUMBERVALUE(RIGHT(P8,LEN(P8)-SEARCH("T",P8,1))),0) -> 0 | Z8: =W8-(W8*Y8)/100 -> 1544.4 | AA8: =IF(P8="DEL0", Z8, Z8+ R8) -> 1591.4 | AB8: =TEXT(K8,"dddd") -> Sunday | AC8: =IF(OR(AB8="Saturday",AB8="Sunday"),"Weekend","Weekday") -> Weekend | AD8: =LEFT(G8,SEARCH("@",G8,1)-1) -> karl.gallagher | AE8: =MID(G8, SEARCH("@",G8,1)+1, SEARCH(".",G8,SEARCH(".",G8,1)+1) - SEARCH("@",G8,1)-1) -> rediffmail | AF8: =B8 & " " & C8 -> Karl Gallagher | AG8: =LEFT(AF8,SEARCH(" ",AF8,1)-1) -> Karl | AH8: =RIGHT(AF8,LEN(AF8)-SEARCH(" ",AF8,1)) -> Gallagher | AI8: =IF(Q8>U8, "Before Time", IF(Q8=U8,"InTime","Late")) -> Before Time | AJ8: =NUMBERVALUE(RIGHT(H8,LEN(H8)-SEARCH("-",H8))) -> #NAME?
A9: CID198 | B9: David | C9: Delacruz | D9: 26 | E9: Female | F9: Los Angeles | G9: david.delacruz@rediffmail.com | H9: +1-7905460592 | I9: USNS Ray, FPO AE 20238 | J9: OID4372 | K9: 45459 | L9: 19:27:45 | M9: PID046 | N9: 363.64 | O9: 3 | P9: FLAT10 | Q9: 2 | R9: 70 | S9: 45464 | T9: 12:36:32 | U9: =VALUE(DATEDIF(K9,S9,"D")) -> 5 | V9: =HOUR(L9) -> 19 | W9: =N9*O9 -> 1090.92 | X9: =W9+R9 -> 1160.92 | Y9: =IFERROR(NUMBERVALUE(RIGHT(P9,LEN(P9)-SEARCH("T",P9,1))),0) -> 0 | Z9: =W9-(W9*Y9)/100 -> 1090.92 | AA9: =IF(P9="DEL0", Z9, Z9+ R9) -> 1160.92 | AB9: =TEXT(K9,"dddd") -> Sunday | AC9: =IF(OR(AB9="Saturday",AB9="Sunday"),"Weekend","Weekday") -> Weekend | AD9: =LEFT(G9,SEARCH("@",G9,1)-1) -> david.delacruz | AE9: =MID(G9, SEARCH("@",G9,1)+1, SEARCH(".",G9,SEARCH(".",G9,1)+1) - SEARCH("@",G9,1)-1) -> rediffmail | AF9: =B9 & " " & C9 -> David Delacruz | AG9: =LEFT(AF9,SEARCH(" ",AF9,1)-1) -> David | AH9: =RIGHT(AF9,LEN(AF9)-SEARCH(" ",AF9,1)) -> Delacruz | AI9: =IF(Q9>U9, "Before Time", IF(Q9=U9,"InTime","Late")) -> Late | AJ9: =NUMBERVALUE(RIGHT(H9,LEN(H9)-SEARCH("-",H9))) -> #NAME?
A10: CID152 | B10: Marcus | C10: Valenzuela | D10: 39 | E10: Male | F10: Phoenix | G10: marcus.valenzuela@yahoo.com | H10: +1-3107089317 | I10: 694 Graham Prairie Apt. 887, Jimenezfurt, MI 33044 | J10: OID3528 | K10: 45040 | L10: 12:07:00 | M10: PID034 | N10: 275.44 | O10: 1 | P10: FLAT8 | Q10: 7 | R10: 63 | S10: 45042 | T10: 23:05:41 | U10: =VALUE(DATEDIF(K10,S10,"D")) -> 2 | V10: =HOUR(L10) -> 12 | W10: =N10*O10 -> 275.44 | X10: =W10+R10 -> 338.44 | Y10: =IFERROR(NUMBERVALUE(RIGHT(P10,LEN(P10)-SEARCH("T",P10,1))),0) -> 0 | Z10: =W10-(W10*Y10)/100 -> 275.44 | AA10: =IF(P10="DEL0", Z10, Z10+ R10) -> 338.44 | AB10: =TEXT(K10,"dddd") -> Monday | AC10: =IF(OR(AB10="Saturday",AB10="Sunday"),"Weekend","Weekday") -> Weekday | AD10: =LEFT(G10,SEARCH("@",G10,1)-1) -> marcus.valenzuela | AE10: =MID(G10, SEARCH("@",G10,1)+1, SEARCH(".",G10,SEARCH(".",G10,1)+1) - SEARCH("@",G10,1)-1) -> yahoo | AF10: =B10 & " " & C10 -> Marcus Valenzuela | AG10: =LEFT(AF10,SEARCH(" ",AF10,1)-1) -> Marcus | AH10: =RIGHT(AF10,LEN(AF10)-SEARCH(" ",AF10,1)) -> Valenzuela | AI10: =IF(Q10>U10, "Before Time", IF(Q10=U10,"InTime","Late")) -> Before Time | AJ10: =NUMBERVALUE(RIGHT(H10,LEN(H10)-SEARCH("-",H10))) -> #NAME?
A11: CID130 | B11: Debra | C11: Rodriguez | D11: 48 | E11: Other | F11: Houston | G11: debra.rodriguez@rediffmail.com | H11: +1-3285345844 | I11: Unit 5964 Box 0721, DPO AP 01840 | J11: OID9634 | K11: 45282 | L11: 13:46:47 | M11: PID033 | N11: 48.45 | O11: 1 | P11: FLAT15 | Q11: 7 | R11: 59 | S11: 45287 | T11: 19:57:06 | U11: =VALUE(DATEDIF(K11,S11,"D")) -> 5 | V11: =HOUR(L11) -> 13 | W11: =N11*O11 -> 48.45 | X11: =W11+R11 -> 107.45 | Y11: =IFERROR(NUMBERVALUE(RIGHT(P11,LEN(P11)-SEARCH("T",P11,1))),0) -> 0 | Z11: =W11-(W11*Y11)/100 -> 48.45 | AA11: =IF(P11="DEL0", Z11, Z11+ R11) -> 107.45 | AB11: =TEXT(K11,"dddd") -> Friday | AC11: =IF(OR(AB11="Saturday",AB11="Sunday"),"Weekend","Weekday") -> Weekday | AD11: =LEFT(G11,SEARCH("@",G11,1)-1) -> debra.rodriguez | AE11: =MID(G11, SEARCH("@",G11,1)+1, SEARCH(".",G11,SEARCH(".",G11,1)+1) - SEARCH("@",G11,1)-1) -> rediffmail | AF11: =B11 & " " & C11 -> Debra Rodriguez | AG11: =LEFT(AF11,SEARCH(" ",AF11,1)-1) -> Debra | AH11: =RIGHT(AF11,LEN(AF11)-SEARCH(" ",AF11,1)) -> Rodriguez | AI11: =IF(Q11>U11, "Before Time", IF(Q11=U11,"InTime","Late")) -> Before Time | AJ11: =NUMBERVALUE(RIGHT(H11,LEN(H11)-SEARCH("-",H11))) -> #NAME?
A12: CID115 | B12: Karl | C12: Gallagher | D12: 60 | E12: Other | F12: Phoenix | G12: karl.gallagher@rediffmail.com | H12: +1-2802179041 | I12: 5016 Snow Mountains Apt. 063, New Seanport, WY 41492 | J12: OID1905 | K12: 45588 | L12: 17:21:43 | M12: PID046 | N12: 363.64 | O12: 4 | P12: DEL0 | Q12: 2 | R12: 35 | S12: 45590 | T12: 08:00:35 | U12: =VALUE(DATEDIF(K12,S12,"D")) -> 2 | V12: =HOUR(L12) -> 17 | W12: =N12*O12 -> 1454.56 | X12: =W12+R12 -> 1489.56 | Y12: =IFERROR(NUMBERVALUE(RIGHT(P12,LEN(P12)-SEARCH("T",P12,1))),0) -> 0 | Z12: =W12-(W12*Y12)/100 -> 1454.56 | AA12: =IF(P12="DEL0", Z12, Z12+ R12) -> 1454.56 | AB12: =TEXT(K12,"dddd") -> Wednesday | AC12: =IF(OR(AB12="Saturday",AB12="Sunday"),"Weekend","Weekday") -> Weekday | AD12: =LEFT(G12,SEARCH("@",G12,1)-1) -> karl.gallagher | AE12: =MID(G12, SEARCH("@",G12,1)+1, SEARCH(".",G12,SEARCH(".",G12,1)+1) - SEARCH("@",G12,1)-1) -> rediffmail | AF12: =B12 & " " & C12 -> Karl Gallagher | AG12: =LEFT(AF12,SEARCH(" ",AF12,1)-1) -> Karl | AH12: =RIGHT(AF12,LEN(AF12)-SEARCH(" ",AF12,1)) -> Gallagher | AI12: =IF(Q12>U12, "Before Time", IF(Q12=U12,"InTime","Late")) -> InTime | AJ12: =NUMBERVALUE(RIGHT(H12,LEN(H12)-SEARCH("-",H12))) -> #NAME?
A13: CID101 | B13: Bobby | C13: Forbes | D13: 20 | E13: Male | F13: Los Angeles | G13: bobby.forbes@gmail.com | H13: +1-2319684657 | I13: 3079 John Parkway Suite 961, Port Kristaview, MT 91019 | J13: OID3136 | K13: 45498 | L13: 15:09:49 | M13: PID007 | N13: 257.06 | O13: 3 | P13: DEL0 | Q13: 7 | R13: 62 | S13: 45499 | T13: 22:54:40 | U13: =VALUE(DATEDIF(K13,S13,"D")) -> 1 | V13: =HOUR(L13) -> 15 | W13: =N13*O13 -> 771.18 | X13: =W13+R13 -> 833.18 | Y13: =IFERROR(NUMBERVALUE(RIGHT(P13,LEN(P13)-SEARCH("T",P13,1))),0) -> 0 | Z13: =W13-(W13*Y13)/100 -> 771.18 | AA13: =IF(P13="DEL0", Z13, Z13+ R13) -> 771.18 | AB13: =TEXT(K13,"dddd") -> Thursday | AC13: =IF(OR(AB13="Saturday",AB13="Sunday"),"Weekend","Weekday") -> Weekday | AD13: =LEFT(G13,SEARCH("@",G13,1)-1) -> bobby.forbes | AE13: =MID(G13, SEARCH("@",G13,1)+1, SEARCH(".",G13,SEARCH(".",G13,1)+1) - SEARCH("@",G13,1)-1) -> gmail | AF13: =B13 & " " & C13 -> Bobby Forbes | AG13: =LEFT(AF13,SEARCH(" ",AF13,1)-1) -> Bobby | AH13: =RIGHT(AF13,LEN(AF13)-SEARCH(" ",AF13,1)) -> Forbes | AI13: =IF(Q13>U13, "Before Time", IF(Q13=U13,"InTime","Late")) -> Before Time | AJ13: =NUMBERVALUE(RIGHT(H13,LEN(H13)-SEARCH("-",H13))) -> #NAME?
... A501: CID158 | B501: Angela | C501: Evans | D501: 52 | E501: Other | F501: Houston | G501: angela.evans@outlook.com | H501: +1-5064601873 | I501: 16031 David Mountain Suite 431, Susanborough, PA 01910 | J501: OID6847 | K501: 45501 | L501: 17:02:09 | M501: PID010 | N501: 44.5 | O501: 4 | P501: DEL0 | Q501: 3 | R501: 45 | S501: 45504 | T501: 05:55:32 | U501: =VALUE(DATEDIF(K501,S501,"D")) -> 3 | V501: =HOUR(L501) -> 17 | W501: =N501*O501 -> 178 | X501: =W501+R501 -> 223 | Y501: =IFERROR(NUMBERVALUE(RIGHT(P501,LEN(P501)-SEARCH("T",P501,1))),0) -> 0 | Z501: =W501-(W501*Y501)/100 -> 178 | AA501: =IF(P501="DEL0", Z501, Z501+ R501) -> 178 | AB501: =TEXT(K501,"dddd") -> Sunday | AC501: =IF(OR(AB501="Saturday",AB501="Sunday"),"Weekend","Weekday") -> Weekend | AD501: =LEFT(G501,SEARCH("@",G501,1)-1) -> angela.evans | AE501: =MID(G501, SEARCH("@",G501,1)+1, SEARCH(".",G501,SEARCH(".",G501,1)+1) - SEARCH("@",G501,1)-1) -> outlook | AF501: =B501 & " " & C501 -> Angela Evans | AG501: =LEFT(AF501,SEARCH(" ",AF501,1)-1) -> Angela | AH501: =RIGHT(AF501,LEN(AF501)-SEARCH(" ",AF501,1)) -> Evans | AI501: =IF(Q501>U501, "Before Time", IF(Q501=U501,"InTime","Late")) -> InTime | AJ501: =NUMBERVALUE(RIGHT(H501,LEN(H501)-SEARCH("-",H501))) -> #NAME?

Sheet Answers
B2: Ans1)
B3: Count of Unique Customers
C4: {=COUNTA(UNIQUE(data!$A$2:$A$501))} -> 100 | D4: =FORMULATEXT(C4) -> =COUNTA(UNIQUE(data!$A$2:$A$501))
B6: Ans2)
B7: Count of Distinct Products
B8: Unique Products | C8: {=COUNTA(UNIQUE(data!L2:L501))} -> 50 | D8: =FORMULATEXT(C8) -> =COUNTA(UNIQUE(data!L2:L501))
B10: Ans3)
B11: Solved in Solutions Sheet
B12: Days to Deliver | C12: VALUE(DATEDIF(K2,S2,"D"))
B14: Ans4)
B15: Solved in Solutions Sheet
B16: Amount | C16: N2*O2
B18: Ans5)
B19: Solved in Solutions Sheet
B20: Amt_with_del_Chrg | C20: W2+R2
B22: Ans6)
B23: Solved in Solutions Sheet
B24: Discount_Percent | C24: IFERROR(NUMBERVALUE(RIGHT(P2,LEN(P2)-SEARCH("T",P2,1))),0)
B26: Ans7)
B27: Solved in Solutions Sheet
B28: Discounted Amount | C28: W2-(W2*Y2)/100
B29: Final Amount | C29: IF(P2="DEL0", Z2, Z2+ R2)
B32: Ans8)
B33: Solved in Solutions Sheet
B34: Full Name | C34: B2 & " " & C2
B37: Ans9)
B38: Solved in Solutions Sheet
B39: Fname | C39: LEFT(AF2,SEARCH(" ",AF2,1)-1)
B40: Lname | C40: RIGHT(AF2,LEN(AF2)-SEARCH(" ",AF2,1))
B43: Ans10)
B44: Solved in Solutions Sheet
B45: Mobile Number | C45: NUMBERVALUE(RIGHT(H2,LEN(H2)-SEARCH("-",H2)))
B48: Ans11)
B49: Solved in Solutions Sheet
B50: Order Day | C50: TEXT(K2,"dddd")
B53: Ans12)
B54: Solved in Solutions Sheet
B55: Is_Weekend | C55: IF(OR(AB2="Saturday",AB2="Sunday"),"Weekend","Weekday")
B56: Weekday | C56: =COUNTIF(Solutions!AC2:AC501,B56) -> 357 | D56: =FORMULATEXT(C56) -> =COUNTIF(Solutions!AC2:AC501,B56)
B57: Weekend | C57: =COUNTIF(Solutions!AC2:AC501,B57) -> 143 | D57: =FORMULATEXT(C57) -> =COUNTIF(Solutions!AC2:AC501,B57)
...
